<?xml version="1.0"?>
<robot name="robotix_crane">

  <!-- Base Link -->
  <link name="base_link">
    <visual>
      <geometry>
        <cylinder length="0.1" radius="0.35"/>
      </geometry>
      <material name="base_color">
        <color rgba="0.3 0.3 0.3 1"/>
      </material>
    </visual>
    <collision>
      <geometry>
        <cylinder length="0.1" radius="0.35"/>
      </geometry>
    </collision>
    <inertial>
      <mass value="10"/>
      <inertia ixx="1" ixy="0" ixz="0" iyy="1" iyz="0" izz="1"/>
    </inertial>
  </link>

  <!-- Column Link -->
  <link name="column">
    <visual>
      <geometry>
        <box size="0.18 2.0 0.05"/>
      </geometry>
      <material name="column_color">
        <color rgba="0.5 0.5 0.5 1"/>
      </material>
    </visual>
    <collision>
      <geometry>
        <box size="0.18 2.0 0.05"/>
      </geometry>
    </collision>
    <inertial>
      <mass value="15"/>
      <inertia ixx="1" ixy="0" ixz="0" iyy="1" iyz="0" izz="1"/>
    </inertial>
  </link>

  <!-- Upper Arm Link -->
  <link name="upper_arm">
    <visual>
      <geometry>
        <box size="0.75 0.18 0.04"/>
      </geometry>
      <material name="arm_color">
        <color rgba="0.7 0.7 0.7 1"/>
      </material>
    </visual>
    <collision>
      <geometry>
        <box size="0.75 0.18 0.04"/>
      </geometry>
    </collision>
    <inertial>
      <mass value="8"/>
      <inertia ixx="1" ixy="0" ixz="0" iyy="1" iyz="0" izz="1"/>
    </inertial>
  </link>

  <!-- Lower Arm Link -->
  <link name="lower_arm">
    <visual>
      <geometry>
        <box size="0.5 0.12 0.03"/>
      </geometry>
      <material name="arm_color"/>
    </visual>
    <collision>
      <geometry>
        <box size="0.5 0.12 0.03"/>
      </geometry>
    </collision>
    <inertial>
      <mass value="5"/>
      <inertia ixx="1" ixy="0" ixz="0" iyy="1" iyz="0" izz="1"/>
    </inertial>
  </link>

  <!-- Wrist Extension Link -->
  <link name="wrist_extension">
    <visual>
      <geometry>
        <box size="0.15 0.08 0.05"/>
      </geometry>
      <material name="extension_color">
        <color rgba="0.8 0.8 0.8 1"/>
      </material>
    </visual>
    <collision>
      <geometry>
        <box size="0.15 0.08 0.05"/>
      </geometry>
    </collision>
    <inertial>
      <mass value="2"/>
      <inertia ixx="1" ixy="0" ixz="0" iyy="1" iyz="0" izz="1"/>
    </inertial>
  </link>

  <!-- Gripper Link -->
  <link name="gripper">
    <visual>
      <geometry>
        <box size="0.2 0.08 0.05"/>
      </geometry>
      <material name="gripper_color">
        <color rgba="0.9 0.9 0.9 1"/>
      </material>
    </visual>
    <collision>
      <geometry>
        <box size="0.2 0.08 0.05"/>
      </geometry>
    </collision>
    <inertial>
      <mass value="1"/>
      <inertia ixx="1" ixy="0" ixz="0" iyy="1" iyz="0" izz="1"/>
    </inertial>
  </link>

  <!-- Joints -->

  <!-- Swing Joint (Base Rotation) -->
  <joint name="swing_joint" type="revolute">
    <parent link="base_link"/>
    <child link="column"/>
    <origin xyz="0 0.05 0" rpy="0 0 0"/>
    <axis xyz="0 1 0"/>
    <limit lower="-3.14159" upper="3.14159" effort="100" velocity="1"/>
  </joint>

  <!-- Lift Joint (Linear Motion) -->
  <joint name="lift_joint" type="prismatic">
    <parent link="column"/>
    <child link="upper_arm"/>
    <origin xyz="0 1.0 0" rpy="0 0 0"/>
    <axis xyz="0 1 0"/>
    <limit lower="0.2" upper="1.7" effort="100" velocity="0.1"/>
  </joint>

  <!-- Elbow Joint -->
  <joint name="elbow_joint" type="revolute">
    <parent link="upper_arm"/>
    <child link="lower_arm"/>
    <origin xyz="0.375 0 0" rpy="0 0 0"/>
    <axis xyz="0 1 0"/>
    <limit lower="-3.14159" upper="3.14159" effort="100" velocity="1"/>
  </joint>

  <!-- Wrist Joint -->
  <joint name="wrist_joint" type="revolute">
    <parent link="lower_arm"/>
    <child link="wrist_extension"/>
    <origin xyz="0.25 0 0" rpy="0 0 0"/>
    <axis xyz="0 1 0"/>
    <limit lower="-3.14159" upper="3.14159" effort="100" velocity="1"/>
  </joint>

  <!-- Gripper Joint -->
  <joint name="gripper_joint" type="prismatic">
    <parent link="wrist_extension"/>
    <child link="gripper"/>
    <origin xyz="0.075 0 0" rpy="0 0 0"/>
    <axis xyz="0 0 1"/>
    <limit lower="0" upper="0.2" effort="50" velocity="0.1"/>
  </joint>

</robot> 